2018-08-02 14:34:52,290 INFO: Microblog startup [in /home/richard/Dev/microblog/app/__init__.py:45]
2018-08-02 14:35:30,596 ERROR: Exception on /edit_profile [POST] [in /home/richard/Dev/microblog/venv/lib/python3.6/site-packages/flask/app.py:1761]
Traceback (most recent call last):
  File "/home/richard/Dev/microblog/venv/lib/python3.6/site-packages/sqlalchemy/engine/base.py", line 1193, in _execute_context
    context)
  File "/home/richard/Dev/microblog/venv/lib/python3.6/site-packages/sqlalchemy/engine/default.py", line 509, in do_execute
    cursor.execute(statement, parameters)
sqlite3.IntegrityError: UNIQUE constraint failed: user.username

The above exception was the direct cause of the following exception:

Traceback (most recent call last):
  File "/home/richard/Dev/microblog/venv/lib/python3.6/site-packages/flask/app.py", line 2292, in wsgi_app
    response = self.full_dispatch_request()
  File "/home/richard/Dev/microblog/venv/lib/python3.6/site-packages/flask/app.py", line 1815, in full_dispatch_request
    rv = self.handle_user_exception(e)
  File "/home/richard/Dev/microblog/venv/lib/python3.6/site-packages/flask/app.py", line 1718, in handle_user_exception
    reraise(exc_type, exc_value, tb)
  File "/home/richard/Dev/microblog/venv/lib/python3.6/site-packages/flask/_compat.py", line 35, in reraise
    raise value
  File "/home/richard/Dev/microblog/venv/lib/python3.6/site-packages/flask/app.py", line 1813, in full_dispatch_request
    rv = self.dispatch_request()
  File "/home/richard/Dev/microblog/venv/lib/python3.6/site-packages/flask/app.py", line 1799, in dispatch_request
    return self.view_functions[rule.endpoint](**req.view_args)
  File "/home/richard/Dev/microblog/venv/lib/python3.6/site-packages/flask_login/utils.py", line 261, in decorated_view
    return func(*args, **kwargs)
  File "/home/richard/Dev/microblog/app/routes.py", line 91, in edit_profile
    db.session.commit()
  File "/home/richard/Dev/microblog/venv/lib/python3.6/site-packages/sqlalchemy/orm/scoping.py", line 153, in do
    return getattr(self.registry(), name)(*args, **kwargs)
  File "/home/richard/Dev/microblog/venv/lib/python3.6/site-packages/sqlalchemy/orm/session.py", line 943, in commit
    self.transaction.commit()
  File "/home/richard/Dev/microblog/venv/lib/python3.6/site-packages/sqlalchemy/orm/session.py", line 467, in commit
    self._prepare_impl()
  File "/home/richard/Dev/microblog/venv/lib/python3.6/site-packages/sqlalchemy/orm/session.py", line 447, in _prepare_impl
    self.session.flush()
  File "/home/richard/Dev/microblog/venv/lib/python3.6/site-packages/sqlalchemy/orm/session.py", line 2254, in flush
    self._flush(objects)
  File "/home/richard/Dev/microblog/venv/lib/python3.6/site-packages/sqlalchemy/orm/session.py", line 2380, in _flush
    transaction.rollback(_capture_exception=True)
  File "/home/richard/Dev/microblog/venv/lib/python3.6/site-packages/sqlalchemy/util/langhelpers.py", line 66, in __exit__
    compat.reraise(exc_type, exc_value, exc_tb)
  File "/home/richard/Dev/microblog/venv/lib/python3.6/site-packages/sqlalchemy/util/compat.py", line 249, in reraise
    raise value
  File "/home/richard/Dev/microblog/venv/lib/python3.6/site-packages/sqlalchemy/orm/session.py", line 2344, in _flush
    flush_context.execute()
  File "/home/richard/Dev/microblog/venv/lib/python3.6/site-packages/sqlalchemy/orm/unitofwork.py", line 391, in execute
    rec.execute(self)
  File "/home/richard/Dev/microblog/venv/lib/python3.6/site-packages/sqlalchemy/orm/unitofwork.py", line 556, in execute
    uow
  File "/home/richard/Dev/microblog/venv/lib/python3.6/site-packages/sqlalchemy/orm/persistence.py", line 177, in save_obj
    mapper, table, update)
  File "/home/richard/Dev/microblog/venv/lib/python3.6/site-packages/sqlalchemy/orm/persistence.py", line 768, in _emit_update_statements
    execute(statement, multiparams)
  File "/home/richard/Dev/microblog/venv/lib/python3.6/site-packages/sqlalchemy/engine/base.py", line 948, in execute
    return meth(self, multiparams, params)
  File "/home/richard/Dev/microblog/venv/lib/python3.6/site-packages/sqlalchemy/sql/elements.py", line 269, in _execute_on_connection
    return connection._execute_clauseelement(self, multiparams, params)
  File "/home/richard/Dev/microblog/venv/lib/python3.6/site-packages/sqlalchemy/engine/base.py", line 1060, in _execute_clauseelement
    compiled_sql, distilled_params
  File "/home/richard/Dev/microblog/venv/lib/python3.6/site-packages/sqlalchemy/engine/base.py", line 1200, in _execute_context
    context)
  File "/home/richard/Dev/microblog/venv/lib/python3.6/site-packages/sqlalchemy/engine/base.py", line 1413, in _handle_dbapi_exception
    exc_info
  File "/home/richard/Dev/microblog/venv/lib/python3.6/site-packages/sqlalchemy/util/compat.py", line 265, in raise_from_cause
    reraise(type(exception), exception, tb=exc_tb, cause=cause)
  File "/home/richard/Dev/microblog/venv/lib/python3.6/site-packages/sqlalchemy/util/compat.py", line 248, in reraise
    raise value.with_traceback(tb)
  File "/home/richard/Dev/microblog/venv/lib/python3.6/site-packages/sqlalchemy/engine/base.py", line 1193, in _execute_context
    context)
  File "/home/richard/Dev/microblog/venv/lib/python3.6/site-packages/sqlalchemy/engine/default.py", line 509, in do_execute
    cursor.execute(statement, parameters)
sqlalchemy.exc.IntegrityError: (sqlite3.IntegrityError) UNIQUE constraint failed: user.username [SQL: 'UPDATE user SET username=?, about_me=? WHERE user.id = ?'] [parameters: ('susan', 'just something!', 2)] (Background on this error at: http://sqlalche.me/e/gkpj)
2018-08-02 15:38:13,501 INFO: Microblog startup [in /home/richard/Dev/microblog/app/__init__.py:45]
2018-08-02 16:01:30,129 INFO: Microblog startup [in /home/richard/Dev/microblog/app/__init__.py:45]
2018-08-02 16:01:41,236 INFO: Microblog startup [in /home/richard/Dev/microblog/app/__init__.py:45]
2018-08-02 16:39:35,572 INFO: Microblog startup [in /home/richard/Dev/microblog/app/__init__.py:45]
2018-08-02 16:48:08,520 INFO: Microblog startup [in /home/richard/Dev/microblog/app/__init__.py:45]
2018-08-02 18:15:08,009 INFO: Microblog startup [in /home/richard/Dev/microblog/app/__init__.py:45]
2018-08-02 18:27:28,821 INFO: Microblog startup [in /home/richard/Dev/microblog/app/__init__.py:45]
2018-08-02 18:27:31,983 ERROR: Exception on /index [GET] [in /home/richard/Dev/microblog/venv/lib/python3.6/site-packages/flask/app.py:1761]
Traceback (most recent call last):
  File "/home/richard/Dev/microblog/venv/lib/python3.6/site-packages/flask/app.py", line 2292, in wsgi_app
    response = self.full_dispatch_request()
  File "/home/richard/Dev/microblog/venv/lib/python3.6/site-packages/flask/app.py", line 1815, in full_dispatch_request
    rv = self.handle_user_exception(e)
  File "/home/richard/Dev/microblog/venv/lib/python3.6/site-packages/flask/app.py", line 1718, in handle_user_exception
    reraise(exc_type, exc_value, tb)
  File "/home/richard/Dev/microblog/venv/lib/python3.6/site-packages/flask/_compat.py", line 35, in reraise
    raise value
  File "/home/richard/Dev/microblog/venv/lib/python3.6/site-packages/flask/app.py", line 1813, in full_dispatch_request
    rv = self.dispatch_request()
  File "/home/richard/Dev/microblog/venv/lib/python3.6/site-packages/flask/app.py", line 1799, in dispatch_request
    return self.view_functions[rule.endpoint](**req.view_args)
  File "/home/richard/Dev/microblog/venv/lib/python3.6/site-packages/flask_login/utils.py", line 261, in decorated_view
    return func(*args, **kwargs)
  File "/home/richard/Dev/microblog/app/routes.py", line 32, in index
    return render_template('index.html', title='Home Page', form=form, posts=posts)
  File "/home/richard/Dev/microblog/venv/lib/python3.6/site-packages/flask/templating.py", line 135, in render_template
    context, ctx.app)
  File "/home/richard/Dev/microblog/venv/lib/python3.6/site-packages/flask/templating.py", line 117, in _render
    rv = template.render(context)
  File "/home/richard/Dev/microblog/venv/lib/python3.6/site-packages/jinja2/asyncsupport.py", line 76, in render
    return original_render(self, *args, **kwargs)
  File "/home/richard/Dev/microblog/venv/lib/python3.6/site-packages/jinja2/environment.py", line 1008, in render
    return self.environment.handle_exception(exc_info, True)
  File "/home/richard/Dev/microblog/venv/lib/python3.6/site-packages/jinja2/environment.py", line 780, in handle_exception
    reraise(exc_type, exc_value, tb)
  File "/home/richard/Dev/microblog/venv/lib/python3.6/site-packages/jinja2/_compat.py", line 37, in reraise
    raise value.with_traceback(tb)
  File "/home/richard/Dev/microblog/app/templates/index.html", line 1, in top-level template code
    {% extends "base.html" %} {% block content %}
  File "/home/richard/Dev/microblog/app/templates/base.html", line 28, in top-level template code
    {% endif %} {% endwith %} {% block content %}{% endblock %}
  File "/home/richard/Dev/microblog/app/templates/index.html", line 15, in block "content"
    {% endif %} {% for post in posts %}
TypeError: 'Pagination' object is not iterable
2018-08-02 18:30:10,201 INFO: Microblog startup [in /home/richard/Dev/microblog/app/__init__.py:45]
2018-08-02 18:37:11,602 INFO: Microblog startup [in /home/richard/Dev/microblog/app/__init__.py:45]
2018-08-02 18:42:38,269 INFO: Microblog startup [in /home/richard/Dev/microblog/app/__init__.py:45]
2018-08-02 18:59:04,062 INFO: Microblog startup [in /home/richard/Dev/microblog/app/__init__.py:47]
2018-08-02 19:07:39,453 INFO: Microblog startup [in /home/richard/Dev/microblog/app/__init__.py:47]
2018-08-02 19:08:21,362 INFO: Microblog startup [in /home/richard/Dev/microblog/app/__init__.py:47]
2018-08-02 19:18:11,285 INFO: Microblog startup [in /home/richard/Dev/microblog/app/__init__.py:47]
2018-08-02 19:18:24,919 INFO: Microblog startup [in /home/richard/Dev/microblog/app/__init__.py:47]
2018-08-02 19:26:26,205 INFO: Microblog startup [in /home/richard/Dev/microblog/app/__init__.py:47]
2018-08-02 19:52:14,715 INFO: Microblog startup [in /home/richard/Dev/microblog/app/__init__.py:47]
